<?xml version="1.0"?>
<robot name="husky">

<!-- Base link is the center of the robot's bottom plate -->
<link name="base_link">
    <visual>
        <origin xyz="0 0 0" rpy="0 0 0" />
        <geometry>
          <mesh filename="file://$(find husky_ual_description)/meshes/base_link_logo.dae" />
        </geometry>
    </visual>
    <collision>
        <origin xyz="0 0 0.1756" rpy="0 0 0" />
        <geometry>
          <mesh filename="file://$(find husky_ual_description)/meshes/base_link_logo.dae" /><!-- <box size="0.7899 0.5709 0.10375"/> -->
        </geometry>
    </collision>
</link>

<!-- Husky chassis -->
<link name="top_chassis_link">
    <visual>
        <origin xyz="0 0 0" rpy="0 0 0" />
        <geometry>
            <mesh filename="file://$(find husky_description)/meshes/top_chassis.dae" />
        </geometry>
    </visual>
</link>
<joint name="top_chassis_joint" type="fixed">
    <parent link="base_link" />
    <child link="top_chassis_link" />
</joint>

<!-- User rails -->
<link name="user_rail_link">
    <visual>
        <geometry>
            <mesh filename="file://$(find husky_description)/meshes/user_rail.dae" />
        </geometry>
    </visual>
</link>
<joint name="user_rail" type="fixed">
    <origin xyz="0.272 0 0.245" rpy="0 0 0" />
    <parent link="base_link" />
    <child link="user_rail_link" />
</joint>

<!-- Front bumper link -->
<link name="front_bumper_link">
    <visual>
        <geometry>
            <mesh filename="file://$(find husky_description)/meshes/bumper.dae" />
        </geometry>
    </visual>
</link>
<joint name="front_bumper" type="fixed">
    <origin xyz="0.48 0 0.091" rpy="0 0 0" />
    <parent link="base_link" />
    <child link="front_bumper_link" />
</joint>

<!-- Rear bumper link -->
<link name="rear_bumper_link">
    <visual>
        <geometry>
            <mesh filename="file://$(find husky_description)/meshes/bumper.dae" />
        </geometry>
    </visual>
</link>
<joint name="rear_bumper" type="fixed">
    <origin xyz="-0.48 0 0.091" rpy="0 0 3.1419" />
    <parent link="base_link" />
    <child link="rear_bumper_link" />
</joint>

<link name="top_plate_link">
    <visual>
        <origin xyz="0 0 0" rpy="0 0 0" />
        <geometry>
            <mesh filename="file://$(find husky_description)/meshes/large_top_plate.dae" />
        </geometry>
    </visual>
    <collision>
        <origin xyz="0 0 0" rpy="0 0 0"/>
        <geometry>
            <mesh filename="file://$(find husky_description)/meshes/large_top_plate_collision.stl" />
        </geometry>
    </collision>
</link>
<joint name="top_plate_joint" type="fixed">
    <parent link="base_link" />
    <child link="top_plate_link"/>
    <origin xyz="0.0812 0 0.225" rpy="0 0 0"/>
</joint>
<!-- Top plate front link -->
<joint name="top_plate_front_joint" type="fixed">
    <parent link="top_plate_link" />
    <child link="top_plate_front_link"/>
    <origin xyz="0.4125 0 0.00672" rpy="0 0 0"/>
</joint>
<!-- Top plate rear link-->
<joint name="top_plate_rear_joint" type="fixed">
    <parent link="top_plate_link" />
    <child link="top_plate_rear_link"/>
    <origin xyz="-0.4125 0 0.00672" rpy="0 0 0"/>
</joint>
<link name="top_plate_front_link"/>
<link name="top_plate_rear_link"/>

<!-- Base footprint is on the ground under the robot -->
<link name="base_footprint">
</link>
<joint name="$base_footprint_joint" type="fixed">
    <origin xyz="0 0 -0.13228" rpy="0 0 0" />
    <parent link="base_link" />
    <child link="base_footprint" />
</joint>

<!-- Mastil -->
<link name="upper_mast_link">
    <visual>
        <geometry>
            <mesh filename="file://$(find husky_ual_description)/meshes/Soporte_mastil.dae" />
        </geometry>
    </visual>
</link>
<joint name="upper_mastil_link" type="fixed">
    <origin xyz="0.05 0 0.45" rpy="0 0 1.57" />
    <parent link="base_link" />
    <child link="upper_mast_link" />
</joint>


<!-- Inertial link stores the robot's inertial information -->
<link name="inertial_link">
    <inertial>
        <mass value="5.034" /> <!--46.034 -->
        <origin xyz="-0.00065 -0.085 0.062" />
        <inertia ixx="0.6022" ixy="-0.02364" ixz="-0.1197" iyy="1.7386" iyz="-0.001544" izz="2.0296" />
    </inertial>
</link>
<joint name="inertial_joint" type="fixed">
    <origin xyz="0 0 0" rpy="0 0 0" />
    <parent link="base_link" />
    <child link="inertial_link" />
</joint>

<link name="structure">
    <inertial>
        <mass value="8.51637756979693" />
        <origin xyz="0 0 0" />
        <inertia ixx="0.258206919587897" ixy="-3.02556764651227E-06" ixz="6.93128254044665E-06" iyy="0.296960404834235" iyz="-0.0001246582297324" izz="0.153127456260744" />
    </inertial>
    <visual>
        <origin xyz="0 0 0" rpy="0 0 0" />
        <geometry>
            <mesh filename="file://$(find husky_ual_description)/meshes/Structure.dae" />
        </geometry>
        <material name="White">
            <color rgba="0.0 0.0 1.0 1.0"/>
        </material>
    </visual>
    <collision>
        <origin xyz="0 0 0" rpy="0 0 0" />
        <geometry>
          <mesh filename="file://$(find husky_ual_description)/meshes/Structure.dae" />
        </geometry>
    </collision>
</link>
<joint name="structure_joint" type="fixed">
    <parent link="base_link" />
    <child link="structure" />
    <origin xyz="0.05 0.0 0.06" rpy="0.0 0 1.5708" />
</joint>

<!-- Husky WHEELS -->
<link name="front_left_wheel">
    <inertial>
        <mass value="2.637" />
        <origin xyz="0 0 0" />
        <inertia  ixx="0.0246688" ixy="0" ixz="0" iyy="0.0246688" iyz="0" izz="0.0441058" />
    </inertial>
    <visual>
        <origin xyz="0 0 0" rpy="0 0 0" />
        <geometry>
            <mesh filename="file://$(find husky_description)/meshes/wheel.dae" />
        </geometry>
    </visual>
    <collision>
        <origin xyz="0 0 0" rpy="1.5708 0 0" />
        <geometry>
            <cylinder length="0.1143" radius="0.17775" />
        </geometry>
    </collision>
</link>
<joint name="front_left_wheel_joint" type="continuous">
    <parent link="base_link"/>
    <child link="front_left_wheel"/>
    <origin rpy="0 0 0" xyz="0.256 0.285475 0.035"/>
    <axis xyz="0 1 0" rpy="0 0 0" />
    <limit effort="10000" velocity="1000"/>
    <joint_properties damping="1.0" friction="1.0"/>
</joint>

<link name="front_right_wheel">
    <inertial>
        <mass value="2.637" />
        <origin xyz="0 0 0" />
        <inertia  ixx="0.0246688" ixy="0" ixz="0" iyy="0.0246688" iyz="0" izz="0.0441058" />
    </inertial>
    <visual>
        <origin xyz="0 0 0" rpy="0 0 0" />
        <geometry>
            <mesh filename="file://$(find husky_description)/meshes/wheel.dae" />
        </geometry>
    </visual>
    <collision>
        <origin xyz="0 0 0" rpy="1.5708 0 0" />
        <geometry>
            <cylinder length="0.1143" radius="0.17775" />
        </geometry>
    </collision>
</link>
<joint name="front_right_wheel_joint" type="continuous">
    <parent link="base_link"/>
    <child link="front_right_wheel"/>
    <origin rpy="0 0 0" xyz="0.256 -0.285475 0.035"/>
    <axis xyz="0 1 0" rpy="0 0 0" />
    <limit effort="10000" velocity="1000"/>
    <joint_properties damping="1.0" friction="1.0"/>
</joint>

<link name="back_left_wheel">
    <inertial>
        <mass value="2.637" />
        <origin xyz="0 0 0" />
        <inertia  ixx="0.0246688" ixy="0" ixz="0" iyy="0.0246688" iyz="0" izz="0.0441058" />
    </inertial>
    <visual>
        <origin xyz="0 0 0" rpy="0 0 0" />
        <geometry>
            <mesh filename="file://$(find husky_description)/meshes/wheel.dae" />
        </geometry>
    </visual>
    <collision>
        <origin xyz="0 0 0" rpy="1.5708 0 0" />
        <geometry>
            <cylinder length="0.1143" radius="0.17775" />
        </geometry>
    </collision>
</link>
<joint name="back_left_wheel_joint" type="continuous">
    <parent link="base_link"/>
    <child link="back_left_wheel"/>
    <origin rpy="0 0 0" xyz="-0.256 0.285475 0.035"/>
    <axis xyz="0 1 0" rpy="0 0 0" />
    <limit effort="10000" velocity="1000"/>
    <joint_properties damping="1.0" friction="1.0"/>
</joint>

<link name="back_right_wheel">
    <inertial>
        <mass value="2.637" />
        <origin xyz="0 0 0" />
        <inertia  ixx="0.0246688" ixy="0" ixz="0" iyy="0.0246688" iyz="0" izz="0.0441058" />
    </inertial>
    <visual>
        <origin xyz="0 0 0" rpy="0 0 0" />
        <geometry>
            <mesh filename="file://$(find husky_description)/meshes/wheel.dae" />
        </geometry>
    </visual>
    <collision>
        <origin xyz="0 0 0" rpy="1.5708 0 0" />
        <geometry>
            <cylinder length="0.1143" radius="0.17775" />
        </geometry>
    </collision>
</link>
<joint name="back_right_wheel_joint" type="continuous">
    <parent link="base_link"/>
    <child link="back_right_wheel"/>
    <origin rpy="0 0 0" xyz="-0.256 -0.285475 0.035"/>
    <axis xyz="0 1 0" rpy="0 0 0" />
    <limit effort="10000" velocity="1000"/>
    <joint_properties damping="1.0" friction="1.0"/>
</joint>

<!-- LASER SCAN-->
<link name="lidar_link">
  <inertial>
    <origin xyz="0 0 0" rpy="0 0 0"/>
    <mass value="0.125"/>
    <inertia ixx="0.001"  ixy="0"  ixz="0" iyy="0.001" iyz="0" izz="0.001" />
  </inertial>

  <collision>
    <origin xyz="0 0 0" rpy="0 0 0"/>
    <geometry>
       <cylinder radius="0.0508" length="0.055"/>
    </geometry>
  </collision>

  <visual>
    <!-- <origin xyz="0.42 0 0.375" rpy="0 0 0"/> -->
    <geometry>
        <mesh filename="file://$(find husky_ual_description)/meshes/os0_32.dae" />
    </geometry>
  </visual>
</link>

<joint name="lidar_joint" type="fixed">
  <parent link="base_link"/>
  <child link="lidar_link"/>
  <origin xyz="0.42 0 0.3" rpy="0 0 0"/>
</joint>


<!-- CAMERA1 AXIS-->
<link name="camera_link">
  <inertial>
    <origin xyz="0 0 0" rpy="0 0 0"/>
    <mass value="0.125"/>
    <inertia ixx="0.001"  ixy="0"  ixz="0" iyy="0.001" iyz="0" izz="0.001" />
  </inertial>

  <collision>
    <origin xyz="0 0 0" rpy="0 0 0"/>
    <geometry>
       <box size = "0.0761 0.0701 0.105"/>
    </geometry>
  </collision>

</link>

<joint name="camera_joint" type="fixed">
  <parent link="base_link"/>
  <child link="camera_link"/>
  <origin xyz="-0.28 0 1.38" rpy="0 0 0"/>
</joint>

<gazebo reference="left_camera_frame">
   <sensor type="multicamera" name="stereo_camera">
     <update_rate>30.0</update_rate>
     <camera name="left">
       <horizontal_fov>1.3962634</horizontal_fov>
       <image>
         <width>800</width>
         <height>800</height>
         <format>R8G8B8</format>
       </image>
       <clip>
         <near>0.02</near>
         <far>300</far>
       </clip>
       <noise>
         <type>gaussian</type>
         <mean>0.0</mean>
         <stddev>0.007</stddev>
       </noise>
     </camera>
     <camera name="right">
       <pose>0 -0.07 0 0 0 0</pose>
       <horizontal_fov>1.3962634</horizontal_fov>
       <image>
         <width>800</width>
         <height>800</height>
         <format>R8G8B8</format>
       </image>
       <clip>
         <near>0.02</near>
         <far>300</far>
       </clip>
       <noise>
         <type>gaussian</type>
         <mean>0.0</mean>
         <stddev>0.007</stddev>
       </noise>
     </camera>
     <plugin name="stereo_camera_controller" filename="libgazebo_ros_multicamera.so">
        <ros>
            <remapping>~/out:=camera</remapping>
        </ros>
        <output_type>sensor_msgs/Image</output_type>
        <frame_name>camera_link</frame_name>
       <alwaysOn>true</alwaysOn>
       <updateRate>0.0</updateRate>
       <cameraName>bumblebee/camera</cameraName>
       <imageTopicName>image_raw</imageTopicName>
       <cameraInfoTopicName>camera_info</cameraInfoTopicName>
       <frameName>left_camera_optical_frame</frameName>
       <!--<rightFrameName>right_camera_optical_frame</rightFrameName>-->
       <hackBaseline>0.07</hackBaseline>
       <distortionK1>0.0</distortionK1>
       <distortionK2>0.0</distortionK2>
       <distortionK3>0.0</distortionK3>
       <distortionT1>0.0</distortionT1>
       <distortionT2>0.0</distortionT2>
     </plugin>
   </sensor>
</gazebo>

<!-- IMU Link is the standard mounting position for the UM6 IMU.-->
<!-- Can be modified with environment variables in /etc/ros/setup.bash -->
<link name="imu_link">
    <visual>
        <geometry>
          <box size="0.1 0.1 0.1"/>
        </geometry>
    </visual>
    <collision>
        <geometry>
          <box size="0.1 0.1 0.1"/>
        </geometry>
    </collision>
</link>
<joint name="imu_joint" type="fixed">
    <parent link="base_link" />
    <child link="imu_link" />
    <origin xyz="0.19 -0.15 0.214" rpy="3.1415 -1.5708 3.1416" />
</joint>

 <!-- JOINT PUBLISHER -->
<gazebo>
    <plugin name="husky_ual_joint_state" filename="libgazebo_ros_joint_state_publisher.so">
      <ros>
          <remapping>~/out:=joint_states</remapping>
      </ros>
      <update_rate>30</update_rate>

      <joint_name>front_left_wheel_joint</joint_name>
      <joint_name>front_right_wheel_joint</joint_name>
      <joint_name>back_left_wheel_joint</joint_name>
      <joint_name>back_right_wheel_joint</joint_name>
      
    </plugin>
</gazebo>
  
  <!-- Differential drive -->
<gazebo>
    <plugin name='skid_steer_drive' filename='libgazebo_ros_diff_drive.so'>
        <update_rate>100.0</update_rate>
        <num_wheel_pairs>2</num_wheel_pairs>
        <left_joint>front_left_wheel_joint</left_joint>
        <right_joint>front_right_wheel_joint</right_joint>
        <left_joint>back_left_wheel_joint</left_joint>
        <right_joint>back_right_wheel_joint</right_joint>
        <wheel_separation>0.5709</wheel_separation>
        <wheel_separation>0.5709</wheel_separation>
        <wheel_diameter>0.3555</wheel_diameter>
        <wheel_diameter>0.3555</wheel_diameter>
        <robot_base_frame>base_link</robot_base_frame>
        <max_wheel_torque>35</max_wheel_torque>
        <max_wheel_acceleration>5.0</max_wheel_acceleration>
        <ros>
          <!-- Set namespace -->
          <!-- Remap default topics -->
          <remapping>cmd_vel:=cmd_vel</remapping>
          <remapping>odom:=odom</remapping>
        </ros>
        <!-- output -->
        <publish_odom>true</publish_odom>
        <publish_odom_tf>true</publish_odom_tf>
        <publish_wheel_tf>true</publish_wheel_tf>
        <odometry_frame>odom</odometry_frame>
    </plugin>
</gazebo>

<gazebo reference="imu_link">
    <gravity>true</gravity>
    <sensor name="imu_sensor" type="imu">
      <always_on>true</always_on>
      <update_rate>100</update_rate>
      <visualize>true</visualize>
      <!-- <topic>imu</topic> -->
      <plugin filename="libgazebo_ros_imu_sensor.so" name="imu_plugin">
        <topicName>imu</topicName>
        <bodyName>imu_link</bodyName>
        <updateRateHZ>10.0</updateRateHZ>
        <gaussianNoise>0.0</gaussianNoise>
        <xyzOffset>0 0 0</xyzOffset>
        <rpyOffset>0 0 0</rpyOffset>
        <frameName>imu_link</frameName>
        <initialOrientationAsReference>false</initialOrientationAsReference>
      </plugin>
      <pose>0 0 0 0 0 0</pose>
    </sensor>
  </gazebo>



</robot>
